Tests that evaluating an expression with an exception in the console provide correct exception information.

        function foo()
        {
            throw {a:239};
        }
        function boo()
        {
            foo();
        }
        boo();
VM:3 Uncaught Object {a: 239}foo @ VM:3boo @ VM:7(anonymous function) @ VM:9
call frame:foo at :3
call frame:boo at :7
call frame: at :9

